Workbook

Sheet INVENTARIO
A1: INVENTARIO DE MATERIAS PRIMAS
A2: Lotes: 405 | MPs: 294 | Confirmadas: 285 | INCI pendiente: 5 | Sin revisar: 4 | Vencidos: 15 | Críticos: 3 | Stock total: 1,492,541 g
A3: Azul = confirmado | Naranja = pendiente de revisión | Rojo = INCI pendiente | Fila roja/amarilla = alerta vencimiento
A4: MATERIA PRIMA | G4: LOTE
A5: CÓDIGO MP | B5: NOMBRE INCI | C5: NOMBRE COMERCIAL | D5: TIPO | E5: PROVEEDOR | F5: STOCK MÍN.(g) | G5: N° LOTE | H5: CANT. CONTEO(g) | I5: CANT. ACTUAL(g) | J5: ESTANTERÍA | K5: POS. | L5: FECHA VENC. | M5: DÍAS | N5: ESTADO
A6: MP00186 | B6: 4-BUTYLRESORCINOL | C6: 4-Butyl resorcinol | E6: Lyphar | F6: 0 | G6: LYPH250727 | H6: 490 | I6: =IFERROR(H6+SUMPRODUCT((MOVIMIENTOS!$C$2:$C$5000=$A6)*(MOVIMIENTOS!$D$2:$D$5000=$G6)*(MOVIMIENTOS!$B$2:$B$5000="INGRESO")*MOVIMIENTOS!$E$2:$E$5000)-SUMPRODUCT((MOVIMIENTOS!$C$2:$C$5000=$A6)*(MOVIMIENTOS!$D$2:$D$5000=$G6)*(MOVIMIENTOS!$B$2:$B$5000="EGRESO")*MOVIMIENTOS!$E$2:$E$5000),"") | J6: 10 | K6: B | L6: 46594 | M6: =IF(L6="","",L6-TODAY()) -> 468 | N6: VIGENTE
A7: MP00183 | B7: ALPHA-ARBUTIN | C7: Alpha arbutina | E7: Lyphar | F7: 0 | G7: LYPH251012 | H7: 9495 | I7: =IFERROR(H7+SUMPRODUCT((MOVIMIENTOS!$C$2:$C$5000=$A7)*(MOVIMIENTOS!$D$2:$D$5000=$G7)*(MOVIMIENTOS!$B$2:$B$5000="INGRESO")*MOVIMIENTOS!$E$2:$E$5000)-SUMPRODUCT((MOVIMIENTOS!$C$2:$C$5000=$A7)*(MOVIMIENTOS!$D$2:$D$5000=$G7)*(MOVIMIENTOS!$B$2:$B$5000="EGRESO")*MOVIMIENTOS!$E$2:$E$5000),"") | J7: 9 | K7: B | L7: 46671 | M7: =IF(L7="","",L7-TODAY()) -> 545 | N7: VIGENTE
A8: MP00117 | B8: COCOS NUCIFERA OIL | C8: Aceite de coco | E8: Inchemical | F8: 0 | G8: AVC25062025AC | H8: 185 | I8: =IFERROR(H8+SUMPRODUCT((MOVIMIENTOS!$C$2:$C$5000=$A8)*(MOVIMIENTOS!$D$2:$D$5000=$G8)*(MOVIMIENTOS!$B$2:$B$5000="INGRESO")*MOVIMIENTOS!$E$2:$E$5000)-SUMPRODUCT((MOVIMIENTOS!$C$2:$C$5000=$A8)*(MOVIMIENTOS!$D$2:$D$5000=$G8)*(MOVIMIENTOS!$B$2:$B$5000="EGRESO")*MOVIMIENTOS!$E$2:$E$5000),"") | J8: 4 | K8: B | L8: 46563 | M8: =IF(L8="","",L8-TODAY()) -> 437 | N8: VIGENTE
A9: MP00138 | B9: LACTIC ACID | C9: Ácido láctico | F9: 0 | G9: L2506221532 | H9: 0 | I9: =IFERROR(H9+SUMPRODUCT((MOVIMIENTOS!$C$2:$C$5000=$A9)*(MOVIMIENTOS!$D$2:$D$5000=$G9)*(MOVIMIENTOS!$B$2:$B$5000="INGRESO")*MOVIMIENTOS!$E$2:$E$5000)-SUMPRODUCT((MOVIMIENTOS!$C$2:$C$5000=$A9)*(MOVIMIENTOS!$D$2:$D$5000=$G9)*(MOVIMIENTOS!$B$2:$B$5000="EGRESO")*MOVIMIENTOS!$E$2:$E$5000),"") | J9: 5 | K9: B | L9: 46559 | M9: =IF(L9="","",L9-TODAY()) -> 433 | N9: VIGENTE
A10: MP00138 | B10: LACTIC ACID | C10: Ácido láctico | F10: 0 | G10: L2509132207 | H10: 3600 | I10: =IFERROR(H10+SUMPRODUCT((MOVIMIENTOS!$C$2:$C$5000=$A10)*(MOVIMIENTOS!$D$2:$D$5000=$G10)*(MOVIMIENTOS!$B$2:$B$5000="INGRESO")*MOVIMIENTOS!$E$2:$E$5000)-SUMPRODUCT((MOVIMIENTOS!$C$2:$C$5000=$A10)*(MOVIMIENTOS!$D$2:$D$5000=$G10)*(MOVIMIENTOS!$B$2:$B$5000="EGRESO")*MOVIMIENTOS!$E$2:$E$5000),"") | J10: 5 | K10: B | L10: 46642 | M10: =IF(L10="","",L10-TODAY()) -> 516 | N10: VIGENTE
A11: MP00235 | B11: NICOTINAMIDE ADENINE DINUCLEOTIDE | C11: NAD | E11: Lyphar | F11: 0 | G11: LYPH251116 | H11: 225.9 | I11: =IFERROR(H11+SUMPRODUCT((MOVIMIENTOS!$C$2:$C$5000=$A11)*(MOVIMIENTOS!$D$2:$D$5000=$G11)*(MOVIMIENTOS!$B$2:$B$5000="INGRESO")*MOVIMIENTOS!$E$2:$E$5000)-SUMPRODUCT((MOVIMIENTOS!$C$2:$C$5000=$A11)*(MOVIMIENTOS!$D$2:$D$5000=$G11)*(MOVIMIENTOS!$B$2:$B$5000="EGRESO")*MOVIMIENTOS!$E$2:$E$5000),"") | J11: nevera | L11: 46706 | M11: =IF(L11="","",L11-TODAY()) -> 580 | N11: VIGENTE
A12: MP00275 | B12: NICOTINAMIDE MONONUCLEOTIDE | C12: NMN | E12: YTBIO | F12: 0 | G12: YT-M20250309 | H12: 72.9 | I12: =IFERROR(H12+SUMPRODUCT((MOVIMIENTOS!$C$2:$C$5000=$A12)*(MOVIMIENTOS!$D$2:$D$5000=$G12)*(MOVIMIENTOS!$B$2:$B$5000="INGRESO")*MOVIMIENTOS!$E$2:$E$5000)-SUMPRODUCT((MOVIMIENTOS!$C$2:$C$5000=$A12)*(MOVIMIENTOS!$D$2:$D$5000=$G12)*(MOVIMIENTOS!$B$2:$B$5000="EGRESO")*MOVIMIENTOS!$E$2:$E$5000),"") | J12: nevera | L12: 46454 | M12: =IF(L12="","",L12-TODAY()) -> 328 | N12: VIGENTE
A13: MP00189 | B13: ACETYL ZINGERONE | C13: Acetil zingerone | E13: Lyphar | F13: 0 | G13: LYPH250806 | H13: 90 | I13: =IFERROR(H13+SUMPRODUCT((MOVIMIENTOS!$C$2:$C$5000=$A13)*(MOVIMIENTOS!$D$2:$D$5000=$G13)*(MOVIMIENTOS!$B$2:$B$5000="INGRESO")*MOVIMIENTOS!$E$2:$E$5000)-SUMPRODUCT((MOVIMIENTOS!$C$2:$C$5000=$A13)*(MOVIMIENTOS!$D$2:$D$5000=$G13)*(MOVIMIENTOS!$B$2:$B$5000="EGRESO")*MOVIMIENTOS!$E$2:$E$5000),"") | J13: 10 | K13: B | L13: 46604 | M13: =IF(L13="","",L13-TODAY()) -> 478 | N13: VIGENTE
A14: MP00152 | B14: ADENOSINE | C14: Adenosina | E14: Lyphar | F14: 0 | G14: LYPH251025 | I14: =IFERROR(H14+SUMPRODUCT((MOVIMIENTOS!$C$2:$C$5000=$A14)*(MOVIMIENTOS!$D$2:$D$5000=$G14)*(MOVIMIENTOS!$B$2:$B$5000="INGRESO")*MOVIMIENTOS!$E$2:$E$5000)-SUMPRODUCT((MOVIMIENTOS!$C$2:$C$5000=$A14)*(MOVIMIENTOS!$D$2:$D$5000=$G14)*(MOVIMIENTOS!$B$2:$B$5000="EGRESO")*MOVIMIENTOS!$E$2:$E$5000),"") | J14: nevera | L14: 46684 | M14: =IF(L14="","",L14-TODAY()) -> 558 | N14: VIGENTE
A15: MP00152 | B15: ADENOSINE | C15: Adenosina | E15: Lyphar | F15: 0 | G15: LYPH260111 | H15: 50 | I15: =IFERROR(H15+SUMPRODUCT((MOVIMIENTOS!$C$2:$C$5000=$A15)*(MOVIMIENTOS!$D$2:$D$5000=$G15)*(MOVIMIENTOS!$B$2:$B$5000="INGRESO")*MOVIMIENTOS!$E$2:$E$5000)-SUMPRODUCT((MOVIMIENTOS!$C$2:$C$5000=$A15)*(MOVIMIENTOS!$D$2:$D$5000=$G15)*(MOVIMIENTOS!$B$2:$B$5000="EGRESO")*MOVIMIENTOS!$E$2:$E$5000),"") | J15: nevera | L15: 46762 | M15: =IF(L15="","",L15-TODAY()) -> 636 | N15: VIGENTE
A16: MP00223 | B16: SODIUM DNA | C16: ADN vegetal (PDRN) | E16: Inchemical | F16: 0 | G16: 2128525 | H16: 932 | I16: =IFERROR(H16+SUMPRODUCT((MOVIMIENTOS!$C$2:$C$5000=$A16)*(MOVIMIENTOS!$D$2:$D$5000=$G16)*(MOVIMIENTOS!$B$2:$B$5000="INGRESO")*MOVIMIENTOS!$E$2:$E$5000)-SUMPRODUCT((MOVIMIENTOS!$C$2:$C$5000=$A16)*(MOVIMIENTOS!$D$2:$D$5000=$G16)*(MOVIMIENTOS!$B$2:$B$5000="EGRESO")*MOVIMIENTOS!$E$2:$E$5000),"") | J16: 11 | K16: B | L16: 47017 | M16: =IF(L16="","",L16-TODAY()) -> 891 | N16: VIGENTE
A17: MP00085 | B17: MELALEUCA ALTERNIFOLIA LEAF OIL | C17: Aceite esencial árbol de té | E17: Inchemical | F17: 0 | G17: 171248525 | H17: 880 | I17: =IFERROR(H17+SUMPRODUCT((MOVIMIENTOS!$C$2:$C$5000=$A17)*(MOVIMIENTOS!$D$2:$D$5000=$G17)*(MOVIMIENTOS!$B$2:$B$5000="INGRESO")*MOVIMIENTOS!$E$2:$E$5000)-SUMPRODUCT((MOVIMIENTOS!$C$2:$C$5000=$A17)*(MOVIMIENTOS!$D$2:$D$5000=$G17)*(MOVIMIENTOS!$B$2:$B$5000="EGRESO")*MOVIMIENTOS!$E$2:$E$5000),"") | J17: 11 | K17: E | L17: 46875 | M17: =IF(L17="","",L17-TODAY()) -> 749 | N17: VIGENTE
A18: MP00085 | B18: MELALEUCA ALTERNIFOLIA LEAF OIL | C18: Aceite esencial árbol de té | E18: Inchemical | F18: 0 | G18: 91021525 | H18: 770 | I18: =IFERROR(H18+SUMPRODUCT((MOVIMIENTOS!$C$2:$C$5000=$A18)*(MOVIMIENTOS!$D$2:$D$5000=$G18)*(MOVIMIENTOS!$B$2:$B$5000="INGRESO")*MOVIMIENTOS!$E$2:$E$5000)-SUMPRODUCT((MOVIMIENTOS!$C$2:$C$5000=$A18)*(MOVIMIENTOS!$D$2:$D$5000=$G18)*(MOVIMIENTOS!$B$2:$B$5000="EGRESO")*MOVIMIENTOS!$E$2:$E$5000),"") | J18: 11 | K18: E | L18: 46905 | M18: =IF(L18="","",L18-TODAY()) -> 779 | N18: VIGENTE
A19: MP00088 | B19: PELARGONIUM GRAVEOLENS FLOWER OIL | C19: Aceite esencial de geranio | E19: YTBIO | F19: 0 | G19: YT20250815 | I19: =IFERROR(H19+SUMPRODUCT((MOVIMIENTOS!$C$2:$C$5000=$A19)*(MOVIMIENTOS!$D$2:$D$5000=$G19)*(MOVIMIENTOS!$B$2:$B$5000="INGRESO")*MOVIMIENTOS!$E$2:$E$5000)-SUMPRODUCT((MOVIMIENTOS!$C$2:$C$5000=$A19)*(MOVIMIENTOS!$D$2:$D$5000=$G19)*(MOVIMIENTOS!$B$2:$B$5000="EGRESO")*MOVIMIENTOS!$E$2:$E$5000),"") | J19: 11 | K19: B | M19: =IF(L19="","",L19-TODAY())
A20: MP00096 | B20: BOSWELLIA CARTERII RESIN OIL | C20: Aceite esencial de incienso | E20: Inchemical | F20: 0 | G20: L34523 | H20: 193 | I20: =IFERROR(H20+SUMPRODUCT((MOVIMIENTOS!$C$2:$C$5000=$A20)*(MOVIMIENTOS!$D$2:$D$5000=$G20)*(MOVIMIENTOS!$B$2:$B$5000="INGRESO")*MOVIMIENTOS!$E$2:$E$5000)-SUMPRODUCT((MOVIMIENTOS!$C$2:$C$5000=$A20)*(MOVIMIENTOS!$D$2:$D$5000=$G20)*(MOVIMIENTOS!$B$2:$B$5000="EGRESO")*MOVIMIENTOS!$E$2:$E$5000),"") | J20: 4 | K20: B | L20: 46264 | M20: =IF(L20="","",L20-TODAY()) -> 138 | N20: VIGENTE
A21: MP00104 | B21: JASMINUM OFFICINALE OIL | C21: Aceite esencial de jazmín | E21: Inchemical | F21: 0 | G21: 2025112601 | I21: =IFERROR(H21+SUMPRODUCT((MOVIMIENTOS!$C$2:$C$5000=$A21)*(MOVIMIENTOS!$D$2:$D$5000=$G21)*(MOVIMIENTOS!$B$2:$B$5000="INGRESO")*MOVIMIENTOS!$E$2:$E$5000)-SUMPRODUCT((MOVIMIENTOS!$C$2:$C$5000=$A21)*(MOVIMIENTOS!$D$2:$D$5000=$G21)*(MOVIMIENTOS!$B$2:$B$5000="EGRESO")*MOVIMIENTOS!$E$2:$E$5000),"") | J21: 11 | K21: B | M21: =IF(L21="","",L21-TODAY())
A22: MP00039 | B22: LAVANDULA ANGUSTIFOLIA OIL | C22: Aceite esencial de lavanda | E22: Inchemical | F22: 0 | G22: L17923 | H22: 400 | I22: =IFERROR(H22+SUMPRODUCT((MOVIMIENTOS!$C$2:$C$5000=$A22)*(MOVIMIENTOS!$D$2:$D$5000=$G22)*(MOVIMIENTOS!$B$2:$B$5000="INGRESO")*MOVIMIENTOS!$E$2:$E$5000)-SUMPRODUCT((MOVIMIENTOS!$C$2:$C$5000=$A22)*(MOVIMIENTOS!$D$2:$D$5000=$G22)*(MOVIMIENTOS!$B$2:$B$5000="EGRESO")*MOVIMIENTOS!$E$2:$E$5000),"") | J22: 4 | K22: B | M22: =IF(L22="","",L22-TODAY())
A23: MP00091 | B23: MATRICARIA CHAMOMILLA FLOWER OIL | C23: Aceite esencial de manzanilla | E23: Inchemical | F23: 0 | G23: 20072525AM | H23: 830 | I23: =IFERROR(H23+SUMPRODUCT((MOVIMIENTOS!$C$2:$C$5000=$A23)*(MOVIMIENTOS!$D$2:$D$5000=$G23)*(MOVIMIENTOS!$B$2:$B$5000="INGRESO")*MOVIMIENTOS!$E$2:$E$5000)-SUMPRODUCT((MOVIMIENTOS!$C$2:$C$5000=$A23)*(MOVIMIENTOS!$D$2:$D$5000=$G23)*(MOVIMIENTOS!$B$2:$B$5000="EGRESO")*MOVIMIENTOS!$E$2:$E$5000),"") | J23: 11 | K23: E | L23: 46233 | M23: =IF(L23="","",L23-TODAY()) -> 107 | N23: VIGENTE
A24: MP00025 | B24: CITRUS AURANTIUM AMARA FLOWER OIL | C24: Aceite de neroli | E24: Inchemical | F24: 0 | G24: 18290925 | H24: 930 | I24: =IFERROR(H24+SUMPRODUCT((MOVIMIENTOS!$C$2:$C$5000=$A24)*(MOVIMIENTOS!$D$2:$D$5000=$G24)*(MOVIMIENTOS!$B$2:$B$5000="INGRESO")*MOVIMIENTOS!$E$2:$E$5000)-SUMPRODUCT((MOVIMIENTOS!$C$2:$C$5000=$A24)*(MOVIMIENTOS!$D$2:$D$5000=$G24)*(MOVIMIENTOS!$B$2:$B$5000="EGRESO")*MOVIMIENTOS!$E$2:$E$5000),"") | J24: 11 | K24: E | L24: 46488 | M24: =IF(L24="","",L24-TODAY()) -> 362 | N24: VIGENTE
A25: MP00139 | B25: ROSMARINUS OFFICINALIS LEAF OIL | C25: Aceite esencial de romero | E25: Inchemical | F25: 0 | G25: 2030125 | H25: 200 | I25: =IFERROR(H25+SUMPRODUCT((MOVIMIENTOS!$C$2:$C$5000=$A25)*(MOVIMIENTOS!$D$2:$D$5000=$G25)*(MOVIMIENTOS!$B$2:$B$5000="INGRESO")*MOVIMIENTOS!$E$2:$E$5000)-SUMPRODUCT((MOVIMIENTOS!$C$2:$C$5000=$A25)*(MOVIMIENTOS!$D$2:$D$5000=$G25)*(MOVIMIENTOS!$B$2:$B$5000="EGRESO")*MOVIMIENTOS!$E$2:$E$5000),"") | J25: 4 | K25: B | M25: =IF(L25="","",L25-TODAY())
A26: MP00101 | B26: VANILLA PLANIFOLIA FRUIT OIL | C26: Aceite esencial de vainilla | E26: Inchemical | F26: 0 | G26: 2073425AV | H26: 510 | I26: =IFERROR(H26+SUMPRODUCT((MOVIMIENTOS!$C$2:$C$5000=$A26)*(MOVIMIENTOS!$D$2:$D$5000=$G26)*(MOVIMIENTOS!$B$2:$B$5000="INGRESO")*MOVIMIENTOS!$E$2:$E$5000)-SUMPRODUCT((MOVIMIENTOS!$C$2:$C$5000=$A26)*(MOVIMIENTOS!$D$2:$D$5000=$G26)*(MOVIMIENTOS!$B$2:$B$5000="EGRESO")*MOVIMIENTOS!$E$2:$E$5000),"") | J26: 11 | K26: E | L26: 46269 | M26: =IF(L26="","",L26-TODAY()) -> 143 | N26: VIGENTE
A27: MP00192 | B27: ACETYL HEXAPEPTIDE-8 | C27: Acetyl hexapeptide-8 | E27: Lyphar | F27: 0 | G27: LYPH251122 | H27: 9.8 | I27: =IFERROR(H27+SUMPRODUCT((MOVIMIENTOS!$C$2:$C$5000=$A27)*(MOVIMIENTOS!$D$2:$D$5000=$G27)*(MOVIMIENTOS!$B$2:$B$5000="INGRESO")*MOVIMIENTOS!$E$2:$E$5000)-SUMPRODUCT((MOVIMIENTOS!$C$2:$C$5000=$A27)*(MOVIMIENTOS!$D$2:$D$5000=$G27)*(MOVIMIENTOS!$B$2:$B$5000="EGRESO")*MOVIMIENTOS!$E$2:$E$5000),"") | J27: nevera | L27: 46712 | M27: =IF(L27="","",L27-TODAY()) -> 586 | N27: VIGENTE
A28: MP00047 | B28: ALLANTOIN | C28: Alantoína | F28: 0 | G28: 20241202 | H28: 100 | I28: =IFERROR(H28+SUMPRODUCT((MOVIMIENTOS!$C$2:$C$5000=$A28)*(MOVIMIENTOS!$D$2:$D$5000=$G28)*(MOVIMIENTOS!$B$2:$B$5000="INGRESO")*MOVIMIENTOS!$E$2:$E$5000)-SUMPRODUCT((MOVIMIENTOS!$C$2:$C$5000=$A28)*(MOVIMIENTOS!$D$2:$D$5000=$G28)*(MOVIMIENTOS!$B$2:$B$5000="EGRESO")*MOVIMIENTOS!$E$2:$E$5000),"") | J28: 7 | K28: C | L28: 46723 | M28: =IF(L28="","",L28-TODAY()) -> 597 | N28: VIGENTE
A29: MP00047 | B29: ALLANTOIN | C29: Alantoína | F29: 0 | G29: 20250724 | H29: 3239 | I29: =IFERROR(H29+SUMPRODUCT((MOVIMIENTOS!$C$2:$C$5000=$A29)*(MOVIMIENTOS!$D$2:$D$5000=$G29)*(MOVIMIENTOS!$B$2:$B$5000="INGRESO")*MOVIMIENTOS!$E$2:$E$5000)-SUMPRODUCT((MOVIMIENTOS!$C$2:$C$5000=$A29)*(MOVIMIENTOS!$D$2:$D$5000=$G29)*(MOVIMIENTOS!$B$2:$B$5000="EGRESO")*MOVIMIENTOS!$E$2:$E$5000),"") | J29: 7 | K29: C | L29: 46958 | M29: =IF(L29="","",L29-TODAY()) -> 832 | N29: VIGENTE
A30: MP00158 | B30: LACTOBIONIC ACID | C30: Ácido lactobiónico | E30: Lyphar | F30: 0 | G30: LYPH250603 | H30: 1000 | I30: =IFERROR(H30+SUMPRODUCT((MOVIMIENTOS!$C$2:$C$5000=$A30)*(MOVIMIENTOS!$D$2:$D$5000=$G30)*(MOVIMIENTOS!$B$2:$B$5000="INGRESO")*MOVIMIENTOS!$E$2:$E$5000)-SUMPRODUCT((MOVIMIENTOS!$C$2:$C$5000=$A30)*(MOVIMIENTOS!$D$2:$D$5000=$G30)*(MOVIMIENTOS!$B$2:$B$5000="EGRESO")*MOVIMIENTOS!$E$2:$E$5000),"") | J30: 2 | K30: B | L30: 46540 | M30: =IF(L30="","",L30-TODAY()) -> 414 | N30: VIGENTE
A31: MP00044 | B31: ETHANOL | C31: Alcohol etílico 95-96% | F31: 0 | G31: 48151253 | H31: 15154 | I31: =IFERROR(H31+SUMPRODUCT((MOVIMIENTOS!$C$2:$C$5000=$A31)*(MOVIMIENTOS!$D$2:$D$5000=$G31)*(MOVIMIENTOS!$B$2:$B$5000="INGRESO")*MOVIMIENTOS!$E$2:$E$5000)-SUMPRODUCT((MOVIMIENTOS!$C$2:$C$5000=$A31)*(MOVIMIENTOS!$D$2:$D$5000=$G31)*(MOVIMIENTOS!$B$2:$B$5000="EGRESO")*MOVIMIENTOS!$E$2:$E$5000),"") | J31: 5 | K31: B | L31: 46740 | M31: =IF(L31="","",L31-TODAY()) -> 614 | N31: VIGENTE
A32: MP00133 | B32: ISOPROPYL ALCOHOL | C32: Alcohol isopropílico | F32: 0 | G32: IPA250210 | I32: =IFERROR(H32+SUMPRODUCT((MOVIMIENTOS!$C$2:$C$5000=$A32)*(MOVIMIENTOS!$D$2:$D$5000=$G32)*(MOVIMIENTOS!$B$2:$B$5000="INGRESO")*MOVIMIENTOS!$E$2:$E$5000)-SUMPRODUCT((MOVIMIENTOS!$C$2:$C$5000=$A32)*(MOVIMIENTOS!$D$2:$D$5000=$G32)*(MOVIMIENTOS!$B$2:$B$5000="EGRESO")*MOVIMIENTOS!$E$2:$E$5000),"") | J32: 5 | K32: B | L32: 46054 | M32: =IF(L32="","",L32-TODAY()) -> -72 | N32: VENCIDO
A33: MP00216 | B33: ALOE BARBADENSIS LEAF JUICE POWDER | C33: Aloe vera polvo | E33: YTBIO | F33: 0 | G33: YT20241005 | H33: 668.5 | I33: =IFERROR(H33+SUMPRODUCT((MOVIMIENTOS!$C$2:$C$5000=$A33)*(MOVIMIENTOS!$D$2:$D$5000=$G33)*(MOVIMIENTOS!$B$2:$B$5000="INGRESO")*MOVIMIENTOS!$E$2:$E$5000)-SUMPRODUCT((MOVIMIENTOS!$C$2:$C$5000=$A33)*(MOVIMIENTOS!$D$2:$D$5000=$G33)*(MOVIMIENTOS!$B$2:$B$5000="EGRESO")*MOVIMIENTOS!$E$2:$E$5000),"") | J33: 7 | K33: C | L33: 46299 | M33: =IF(L33="","",L33-TODAY()) -> 173 | N33: VIGENTE
A34: MP00217 | B34: ALOE BARBADENSIS LEAF JUICE POWDER | C34: Aloe vera 200X polvo | E34: YTBIO | F34: 0 | G34: YT20240802 | H34: 1715 | I34: =IFERROR(H34+SUMPRODUCT((MOVIMIENTOS!$C$2:$C$5000=$A34)*(MOVIMIENTOS!$D$2:$D$5000=$G34)*(MOVIMIENTOS!$B$2:$B$5000="INGRESO")*MOVIMIENTOS!$E$2:$E$5000)-SUMPRODUCT((MOVIMIENTOS!$C$2:$C$5000=$A34)*(MOVIMIENTOS!$D$2:$D$5000=$G34)*(MOVIMIENTOS!$B$2:$B$5000="EGRESO")*MOVIMIENTOS!$E$2:$E$5000),"") | J34: 7 | K34: C | L34: 46235 | M34: =IF(L34="","",L34-TODAY()) -> 109 | N34: VIGENTE
A35: MPANAC01 | B35: P-ANISIC ACID | C35: P-anisic acid | E35: Bolite | F35: 0 | G35: 2025051601 | I35: =IFERROR(H35+SUMPRODUCT((MOVIMIENTOS!$C$2:$C$5000=$A35)*(MOVIMIENTOS!$D$2:$D$5000=$G35)*(MOVIMIENTOS!$B$2:$B$5000="INGRESO")*MOVIMIENTOS!$E$2:$E$5000)-SUMPRODUCT((MOVIMIENTOS!$C$2:$C$5000=$A35)*(MOVIMIENTOS!$D$2:$D$5000=$G35)*(MOVIMIENTOS!$B$2:$B$5000="EGRESO")*MOVIMIENTOS!$E$2:$E$5000),"") | J35: 12 | K35: B | M35: =IF(L35="","",L35-TODAY())
A36: MP00165 | B36: ANEMARRHENA ASPHODELOIDES ROOT EXTRACT | C36: Anemarrhena root extract | E36: Lyphar | F36: 0 | G36: LYPH250621 | H36: 1000 | I36: =IFERROR(H36+SUMPRODUCT((MOVIMIENTOS!$C$2:$C$5000=$A36)*(MOVIMIENTOS!$D$2:$D$5000=$G36)*(MOVIMIENTOS!$B$2:$B$5000="INGRESO")*MOVIMIENTOS!$E$2:$E$5000)-SUMPRODUCT((MOVIMIENTOS!$C$2:$C$5000=$A36)*(MOVIMIENTOS!$D$2:$D$5000=$G36)*(MOVIMIENTOS!$B$2:$B$5000="EGRESO")*MOVIMIENTOS!$E$2:$E$5000),"") | J36: 2 | K36: B | L36: 46558 | M36: =IF(L36="","",L36-TODAY()) -> 432 | N36: VIGENTE
A37: MP00234 | B37: APIGENIN | C37: Apigenin | E37: YTBIO | F37: 0 | G37: YTA20250325 | H37: 94 | I37: =IFERROR(H37+SUMPRODUCT((MOVIMIENTOS!$C$2:$C$5000=$A37)*(MOVIMIENTOS!$D$2:$D$5000=$G37)*(MOVIMIENTOS!$B$2:$B$5000="INGRESO")*MOVIMIENTOS!$E$2:$E$5000)-SUMPRODUCT((MOVIMIENTOS!$C$2:$C$5000=$A37)*(MOVIMIENTOS!$D$2:$D$5000=$G37)*(MOVIMIENTOS!$B$2:$B$5000="EGRESO")*MOVIMIENTOS!$E$2:$E$5000),"") | J37: 10 | K37: B | L37: 46470 | M37: =IF(L37="","",L37-TODAY()) -> 344 | N37: VIGENTE
A38: MP00230 | B38: ASCORBIC ACID | C38: Vitamina C | E38: YTBIO | F38: 0 | G38: DY2230112024 | I38: =IFERROR(H38+SUMPRODUCT((MOVIMIENTOS!$C$2:$C$5000=$A38)*(MOVIMIENTOS!$D$2:$D$5000=$G38)*(MOVIMIENTOS!$B$2:$B$5000="INGRESO")*MOVIMIENTOS!$E$2:$E$5000)-SUMPRODUCT((MOVIMIENTOS!$C$2:$C$5000=$A38)*(MOVIMIENTOS!$D$2:$D$5000=$G38)*(MOVIMIENTOS!$B$2:$B$5000="EGRESO")*MOVIMIENTOS!$E$2:$E$5000),"") | J38: estibas | L38: 46053 | M38: =IF(L38="","",L38-TODAY()) -> -73 | N38: VENCIDO
A39: MP00230 | B39: ASCORBIC ACID | C39: Vitamina C | E39: YTBIO | F39: 0 | G39: DY2230112024 | H39: 10000 | I39: =IFERROR(H39+SUMPRODUCT((MOVIMIENTOS!$C$2:$C$5000=$A39)*(MOVIMIENTOS!$D$2:$D$5000=$G39)*(MOVIMIENTOS!$B$2:$B$5000="INGRESO")*MOVIMIENTOS!$E$2:$E$5000)-SUMPRODUCT((MOVIMIENTOS!$C$2:$C$5000=$A39)*(MOVIMIENTOS!$D$2:$D$5000=$G39)*(MOVIMIENTOS!$B$2:$B$5000="EGRESO")*MOVIMIENTOS!$E$2:$E$5000),"") | J39: estibas | M39: =IF(L39="","",L39-TODAY())
A40: MP00230 | B40: ASCORBIC ACID | C40: Vitamina C | E40: YTBIO | F40: 0 | G40: YT20250315 | H40: 2800 | I40: =IFERROR(H40+SUMPRODUCT((MOVIMIENTOS!$C$2:$C$5000=$A40)*(MOVIMIENTOS!$D$2:$D$5000=$G40)*(MOVIMIENTOS!$B$2:$B$5000="INGRESO")*MOVIMIENTOS!$E$2:$E$5000)-SUMPRODUCT((MOVIMIENTOS!$C$2:$C$5000=$A40)*(MOVIMIENTOS!$D$2:$D$5000=$G40)*(MOVIMIENTOS!$B$2:$B$5000="EGRESO")*MOVIMIENTOS!$E$2:$E$5000),"") | J40: 7 | K40: F | L40: 46460 | M40: =IF(L40="","",L40-TODAY()) -> 334 | N40: VIGENTE
...

Sheet MOVIMIENTOS
A1: MOVIMIENTOS — INGRESOS Y EGRESOS
A2: FECHA | B2: TIPO | C2: CÓDIGO MP | D2: N° LOTE | E2: CANTIDAD (g) | F2: OBSERVACIONES

Sheet ALERTAS
A1: ALERTAS AUTOMÁTICAS
A3: LOTES VENCIDOS
A4: CÓDIGO MP | B4: NOMBRE COMERCIAL | C4: N° LOTE | D4: CANT. ACTUAL(g) | E4: ESTANTERÍA | F4: DÍAS PARA VENCER
A5: → Filtrar hoja INVENTARIO: ESTADO = "VENCIDO"
A7: LOTES CRÍTICOS — vencen en < 30 días
A8: CÓDIGO MP | B8: NOMBRE COMERCIAL | C8: N° LOTE | D8: CANT. ACTUAL(g) | E8: ESTANTERÍA | F8: DÍAS PARA VENCER
A9: → Filtrar hoja INVENTARIO: ESTADO = "CRÍTICO"
A11: LOTES PRÓXIMOS — vencen en < 90 días
A12: CÓDIGO MP | B12: NOMBRE COMERCIAL | C12: N° LOTE | D12: CANT. ACTUAL(g) | E12: ESTANTERÍA | F12: DÍAS PARA VENCER
A13: → Filtrar hoja INVENTARIO: ESTADO = "PRÓXIMO"
A15: INCI PENDIENTE DE VERIFICACIÓN
A16: CÓDIGO MP | B16: NOMBRE COMERCIAL | C16: N° LOTE | D16: CANT. ACTUAL(g) | E16: ESTANTERÍA | F16: DÍAS PARA VENCER
A17: → Filtrar hoja INVENTARIO: NOMBRE INCI contiene "PENDIENTE INCI"
A19: STOCK BAJO MÍNIMO
A20: CÓDIGO MP | B20: NOMBRE COMERCIAL | C20: N° LOTE | D20: CANT. ACTUAL(g) | E20: ESTANTERÍA | F20: DÍAS PARA VENCER
A21: → Filtrar hoja INVENTARIO: CANT. ACTUAL < STOCK MÍN.
