Workbook

Sheet LISTA CHEQUEO
D1: FORMATO | M1: Código | O1: PRD-PRO-001-F01
M2: Versión | O2: 1
D3: LISTA DE CHEQUEO BATCH RECORD | M3: Página | O3: 1 de 1
M4: Vigencia | O4: Desde: 04-Mar-2025
O5: Hasta: 03-Mar-2028
A7: NOMBRE DEL PRODUCTO | F7: SUERO HIDRATANTE AH 1.5%
A8: LOTE | F8: 252671 | K8: OP | M8: OP-L-131
A9: PRESENTACIÓN | K9: TAMAÑO LOTE (kg) | M9: 40
A10: CLIENTE | F10: ANIMUS LAB
A11: NOTIFICACIÓN SANITARIA | F11: NSOC36908-25CO | K11: UNIDADES APROBADAS/FABRICADAS
A12: FORMA COSMETICA | F12: SOLUCION | K12: FECHA DILIGENCIAMIENTO
A14: VERIFICACIÓN DE DOCUMENTOS
A15: ITEM | B15: DOCUMENTO | L15: CONCEPTO | N15: OBSERVACIONES
A16: 1 | B16: Lista de Chequeo
A17: 2 | B17: Despeje de Linea
A18: 3 | B18: Orden de Producción
A19: 4 | B19: Dispensación de Materias Primas
A20: 5 | B20: Instructivo de Fabricación
A21: 6 | B21: Control Calidad a Granel
A22: 7 | B22: Estado de Aseo de Áreas y Equipos
A23: 8 | B23: Orden y Control de envasado
A24: 9 | B24: Acondicionamiento y Empaque
A25: 10 | B25: Certificado de análisis del Producto Terminado
A26: 11 | B26: Rotulos de materias primas dispensadas
A27: 12 | B27: Inspección de etiqueta
A28: 13 | B28: Inspeccion de Producto Terminado
A29: OBSERVACIONES:
A30: RESPONSABLES DEL PROCESO
A32: JEFE DE PRODUCCIÓN | K32: JEFE DE CONTROL DE CALIDAD
A33: APROBACIÓN
A34: FECHA DE CIERRE
A35: VBO DIRECCIÓN TÉCNICA
A37: CUMPLE: C NO CUMPLE: NC NO APLICA: NA

Sheet DESPEJE DE LINEA
D1: FORMATO | M1: Código | O1: PRD-PRO-001-F02
M2: Versión | O2: 1
D3: DESPEJE DE LINEA | M3: Página | O3: 1 de 1
M4: Vigencia | O4: Desde: 04-Mar-2025
O5: Hasta: 03-Mar-2028
A7: NOMBRE DEL PRODUCTO | G7: ='LISTA CHEQUEO'!F7 -> SUERO HIDRATANTE AH 1.5%
A8: NOTIFICACIÓN SANITARIA | G8: ='LISTA CHEQUEO'!F11 -> NSOC36908-25CO | L8: NÚMERO DE LOTE | N8: ='LISTA CHEQUEO'!F8 -> 252671
A9: FORMA COSMÉTICA | G9: ='LISTA CHEQUEO'!F12 -> SOLUCION | L9: NÚMERO DE OP | N9: ='LISTA CHEQUEO'!M8 -> OP-L-131
A10: TAMAÑO DEL LOTE (Kg) | G10: ='LISTA CHEQUEO'!M9 -> 40 | L10: FECHA DE VENCIMIENTO
A12: SANITIZANTE UTILIZADO:
A13: ÁREAS DE TRABAJO: | G13: DISPENSACIÓN | I13: FABRICACIÓN | K13: ENVASADO | M13: CONTROL DE CALIDAD | O13: ACONDICIONAMIENTO
A14: FECHA
A15: HORA INICIO-HORA FIN
A16: PÁRAMETRO | G16: °T | H16: %H | I16: °T | J16: %H | K16: °T | L16: %H | M16: °T | N16: %H | O16: °T | P16: %H
G18: C | H18: NC | I18: C | J18: NC | K18: C | L18: NC | M18: C | N18: NC | O18: C | P18: NC
A19: El área está libre de materias primas, material de envase y empaque, gráneles, etiquetas, producto terminado y documentación del producto anterior.
A20: ¿Se asegura que las áreas de producción estén limpias y desinfectadas antes de cada lote?
A21: ¿Los formatos de Limpieza de áreas se encuentran diligenciados y al día?
A22: ¿Se acomprueba que todos los equipos están rotulados como "Equipo limpio" y están listos para ser usados?
A23: ¿Se acomprueba que todas las áreas están rotuladas como "Área limpia" y están listas para ser usadas?
A24: El área y sus equipos y/o utensilios se encuentran completamente limpios y con los respectivos rótulos de Limpieza Área / Equipo.
A25: El área se encuentra identificada con el producto en proceso
A26: Las materias primas, material de envase y empaque, graneles, etiquetas y documentación corresponden al producto a trabajar.
A27: ¿Las condiciones ambientales son las idoneas para el proceso?
A28: ¿El formato de registro de condiciones ambientales se encuentra diligenciado y al día?
A29: ¿Los equipos requeridos se encuentran aptos para su uso? (mantenimiento y calibración al día)
A30: ¿Cuenta con los EPP requeridos para el proceso?
... A38: CUMPLE: C NO CUMPLE: NC

Sheet OP
A1: 500 | D1: FORMATO | M1: Código | O1: PRD-PRO-001-F03
M2: Versión | O2: 1
D3: ORDEN DE PRODUCCIÓN | M3: Página | O3: 1 de 1
M4: Vigencia | O4: Desde: 04-Mar-2025
O5: Hasta: 03-Mar-2028
A7: Toda la información contenida en este documento es confidencial, propiedad exclusiva de ESPAGIRIA LABORATORIOS; por lo tanto, no puede ser publicada, reproducida o divulgada para cualquier propósito, sin previa autorización.
A9: NOMBRE DEL PRODUCTO | G9: ='DESPEJE DE LINEA'!G7 -> SUERO HIDRATANTE AH 1.5%
A10: NOTIFICACIÓN SANITARIA | G10: ='DESPEJE DE LINEA'!G8 -> NSOC36908-25CO | K10: NÚMERO DE LOTE | M10: ='DESPEJE DE LINEA'!N8 -> 252671 | N10: FECHA DE VENCIMIENTO
A11: FORMA COSMÉTICA | G11: ='DESPEJE DE LINEA'!G9 -> SOLUCION | K11: NÚMERO O.P | M11: ='DESPEJE DE LINEA'!N9 -> OP-L-131 | N11: HORAS ESTIMADAS
A12: FECHA DE EMISIÓN DE ORDEN | K12: No. UNIDADES A FABRICAR | N12: TAMAÑO DEL LOTE (Kg) | P12: 90
A14: No. | B14: MATERIAS PRIMAS | G14: CODIGO MP | J14: LOTE | M14: % | N14: CANTIDAD TEÓRICA (g)
A15: 1 | B15: AGUA DESIONIZADA | G15: MPAGUAL01 | J15: AD-251981 | M15: 95.21 | N15: =(+$P$12*M15/100)*1000 -> 85689
A16: 2 | B16: GLICERINA | G16: MPGLICLI01 | J16: 021067-25 | M16: 1 | N16: =(+$P$12*M16/100)*1000 -> 900
A17: 3 | B17: FENOXIETANOL | G17: MPFENOLI01 | J17: 871931 | M17: 1 | N17: =(+$P$12*M17/100)*1000 -> 900
A18: 4 | B18: ACIDO HIALURONICO 50 KD (LYPHAR) | G18: MPACHISO01 | J18: LYPH250219 | M18: 0.8 | N18: =(+$P$12*M18/100)*1000 -> 720
A19: 5 | B19: ACIDO HIALURONICO 300 KD (LYPHAR) | G19: MPACHISO02 | J19: LYPH241018 | M19: 0.4 | N19: =(+$P$12*M19/100)*1000 -> 360
A20: 6 | B20: BETAINA | G20: MPBETASO01 | J20: YT-20240405 | M20: 0.35 | N20: =(+$P$12*M20/100)*1000 -> 315
A21: 7 | B21: ACIDO HIALURONICO 1500 KD (LYPHAR) | G21: MPACHISO03 | J21: LYPH250219 | M21: 0.3 | N21: =(+$P$12*M21/100)*1000 -> 270
A22: 8 | B22: ALANTOINA | G22: MPALANSO01 | J22: 20241202 | M22: 0.3 | N22: =(+$P$12*M22/100)*1000 -> 270
A23: 9 | B23: GLUCONOLACTONA | G23: MPGLUCSO01 | J23: YT-G20250419 | M23: 0.3 | N23: =(+$P$12*M23/100)*1000 -> 270
A24: 10 | B24: VITAMINA E POLVO | G24: MPVITESO01 | J24: 022411A014 | M24: 0.2 | N24: =(+$P$12*M24/100)*1000 -> 180
A25: 11 | B25: PANTENOL POLVO | G25: MPPANTSO01 | J25: YT-20250402 | M25: 0.1 | N25: =(+$P$12*M25/100)*1000 -> 90
A26: 12 | B26: BETAGLUCAM | G26: MPBETASO02 | J26: YT-20240219 | M26: 0.03 | N26: =(+$P$12*M26/100)*1000 -> 27
A27: 13 | B27: ALOE VERA | G27: MPALVESO01 | J27: YT-20241005 | M27: 0.01 | N27: =(+$P$12*M27/100)*1000 -> 9
A28: TOTAL | M28: =SUM(M15:M27) -> 100 | N28: =SUM(N15:P27) -> 90000
A29: RECOMENDACIONES GENERALES:
A30: 1.El operario de produccion realiza el despeje de línea verificando la limpieza de las áreas, equipos y utensilios a utilizar , se deben usar en cada etapa de los procesos los elementos de protección personal o equipos de seguridad, se deben diligenciar los formatos de limpieza de áreas y equipos al igual que los formatos de utilización de áreas y equipos.
A31: 2. Para cada etapa del proceso de dispensación, fabricación y envasado el operador de producción, operador de bodega u otra persona encargada del proceso deberán utilizar un dotacion acorde.
A32: 3. El ensamblado de las piezas de tanques de fabricacion y/o equipos de envasado, se debe realizar uilizando guantes durante toda la manipulacion de las piezas, asperjando etanol al 70% en las piezas a ensamblar.
A33: 4. Las materias primas, material de envase y empaque, graneles, etiquetas y documentación corresponden al producto a trabajar.
A34: OBSERVACIONES:
A36: ELABORADO POR | N36: FECHA
G37: Jefe de Producción
A38: REVISADO POR | N38: FECHA
G39: Analista de Control de Calidad o Jefe de control de Calidad
A40: APROBADO POR | N40: FECHA
F41: Dirección Técnica

Sheet DISPENSACIÓN
D1: FORMATO | M1: Código | O1: PRD-PRO-001-F04
M2: Versión | O2: 1
D3: DISPENSACIÓN DE MATERIAS PRIMAS | M3: Página | O3: 1 de 1
M4: Vigencia | O4: Desde: 04-Mar-2025
O5: Hasta: 03-Mar-2028
A7: NOMBRE DEL PRODUCTO | F7: =OP!G9 -> SUERO HIDRATANTE AH 1.5%
A8: NÚMERO DE LOTE | F8: =OP!M10 -> 252671 | H8: FECHA DE INICIO: | N8: FECHA FIN:
A9: NÚMERO OP. | F9: =OP!M11 -> OP-L-131 | H9: HORA INICIO/HORA FIN: | N9: TIEMPO EN HORAS:
A11: DESPEJE Y LIBERACIÓN DEL ÁREA: | N11: SI | P11: NO
A12: Se encuentra diligenciado el campo del área a usar en el formato PRD-PRO-001-F02
A14: NOTA: Pesar las materias primas APROBADAS en el siguiente orden: 1. Solidos; 2. Liquidos; 3. Fragancias; 4. Colorantes
A15: DISPENSADO
A16: CÓDIGO MP | C16: MATERIA PRIMA | H16: % | K16: CANTIDAD TEÓRICA (g) | M16: LOTE | O16: CANTIDAD REAL (g)
A17: =OP!G15 -> MPAGUAL01 | C17: =OP!B15 -> AGUA DESIONIZADA | H17: =OP!M15 -> 95.21 | K17: =OP!N15 -> 85689 | M17: =OP!J15 -> AD-251981
A18: =OP!G16 -> MPGLICLI01 | C18: =OP!B16 -> GLICERINA | H18: =OP!M16 -> 1 | K18: =OP!N16 -> 900 | M18: =OP!J16 -> 021067-25
A19: =OP!G17 -> MPFENOLI01 | C19: =OP!B17 -> FENOXIETANOL | H19: =OP!M17 -> 1 | K19: =OP!N17 -> 900 | M19: =OP!J17 -> 871931
A20: =OP!G18 -> MPACHISO01 | C20: =OP!B18 -> ACIDO HIALURONICO 50 KD (LYPHAR) | H20: =OP!M18 -> 0.8 | K20: =OP!N18 -> 720 | M20: =OP!J18 -> LYPH250219
A21: =OP!G19 -> MPACHISO02 | C21: =OP!B19 -> ACIDO HIALURONICO 300 KD (LYPHAR) | H21: =OP!M19 -> 0.4 | K21: =OP!N19 -> 360 | M21: =OP!J19 -> LYPH241018
A22: =OP!G20 -> MPBETASO01 | C22: =OP!B20 -> BETAINA | H22: =OP!M20 -> 0.35 | K22: =OP!N20 -> 315 | M22: =OP!J20 -> YT-20240405
A23: =OP!G21 -> MPACHISO03 | C23: =OP!B21 -> ACIDO HIALURONICO 1500 KD (LYPHAR) | H23: =OP!M21 -> 0.3 | K23: =OP!N21 -> 270 | M23: =OP!J21 -> LYPH250219
A24: =OP!G22 -> MPALANSO01 | C24: =OP!B22 -> ALANTOINA | H24: =OP!M22 -> 0.3 | K24: =OP!N22 -> 270 | M24: =OP!J22 -> 20241202
A25: =OP!G23 -> MPGLUCSO01 | C25: =OP!B23 -> GLUCONOLACTONA | H25: =OP!M23 -> 0.3 | K25: =OP!N23 -> 270 | M25: =OP!J23 -> YT-G20250419
A26: =OP!G24 -> MPVITESO01 | C26: =OP!B24 -> VITAMINA E POLVO | H26: =OP!M24 -> 0.2 | K26: =OP!N24 -> 180 | M26: =OP!J24 -> 022411A014
A27: =OP!G25 -> MPPANTSO01 | C27: =OP!B25 -> PANTENOL POLVO | H27: =OP!M25 -> 0.1 | K27: =OP!N25 -> 90 | M27: =OP!J25 -> YT-20250402
A28: =OP!G26 -> MPBETASO02 | C28: =OP!B26 -> BETAGLUCAM | H28: =OP!M26 -> 0.03 | K28: =OP!N26 -> 27 | M28: =OP!J26 -> YT-20240219
A29: =OP!G27 -> MPALVESO01 | C29: =OP!B27 -> ALOE VERA | H29: =OP!M27 -> 0.01 | K29: =OP!N27 -> 9 | M29: =OP!J27 -> YT-20241005
A30: Observaciones:
A33: Dispensado por: | K33: Verificado por:
A34: Cargo: | K34: Cargo:
A35: Fecha: | K35: Fecha:

Sheet INSTRUCTIVO FAB
D1: FORMATO | M1: Código | O1: PRD-PRO-001-F05
M2: Versión | O2: 1
D3: INSTRUCTIVO DE FABRICACION | M3: Página | O3: 1 de 1
M4: Vigencia | O4: Desde: 04-Mar-2025
O5: Hasta: 03-Mar-2028
A7: NOMBRE DEL PRODUCTO | F7: =DISPENSACIÓN!F7 -> SUERO HIDRATANTE AH 1.5%
A8: NUMERO DE LOTE | F8: =DISPENSACIÓN!F8 -> 252671 | H8: Fecha de Inicio: | M8: Fecha de Finalización:
A9: NUMERO DE OP | F9: =DISPENSACIÓN!F9 -> OP-L-131 | H9: Hora de Inicio/Hora fin: | M9: Tiempo en Horas:
A11: DESPEJE Y LIBERACION DEL AREA | N11: SI | P11: NO
A12: Se encuentra diligenciado el campo del area a usar ene el formato PRD-001-F02
A14: FABRICACIÓN DE PRODUCTOS
A16: 1. Dispensar en una balanza analítica y adicionar en un recipiente las siguientes materias primas: Agua Desionizada Betaina Alantoina Gluconolactona Vitamina E Polvo Betaglucam Aloe Vera Pantenol Polvo Tome un recipiente, adicione agua desionizada, manteniendo una agitación constante, RPM Real:_______ e incorporar de forma secuencial las materias primas, asegurándose de que cada uno se disuelva completamente.
A17: 2. Dispensar en una balanza analítica y adicionar en un recipiente las siguientes materias primas: Agua Desionizada Acido Hialuronico 50 KD Acido Hialuronico 300 KD Acido Hialuronico 1500 KD Glicerina Tome un recipiente, adicione agua desionizada y en una plancha de calentamiento mantenga una temperatura de 60°C +/-, Temperatura Real_______, tome la glicerina e hidrate lo acidos hialuronicos y poco a poco adicione el agua caliente con agitacion constante RPM Real:_______, hasta total disolucion de la mezcla e incorporar a la fase 1
A18: 3. Dispensar en una balanza analítica y adicionar al recipiente principal la siguiente materia prima: Fenoxietanol Adicione esta materia prima con agitacion constante, RPM Real:_______, despues de haber homogenizado bien las dos fases hasta que se presente una mezcla homogenea.
A19: 4.Tome un recipiente metálico las 3 etapas de premezclado y dejar agitando durante 60 minutos a una velocidad constante de 200 rpm con el agitador hasta que está presente una mezcla homogénea, RPM Real: ______, por último, apague el agitador hasta que la mezcla quede totalmente uniforme.
A21: NOTA: Si al iniciar la fabricación se observa alguna no conformidad o inconsistencia con la materia prima, sea que esta se encuentre con material particulado extraño, coloración no habitual o se evidencia que ha estado expuesta durante su almacenamiento al medio ambiente, se deberá dar aviso al Director tecnico y al analista de control de calidad para que ellos determinen si se usa o no.
A23: Observaciones:
A26: Realizado por: | K26: Verificado por:
A27: Cargo: | K27: Cargo:
A28: Fecha: | K28: Fecha:

Sheet COC GRANEL
D1: FORMATO | I1: Código | J1: COC-PRO-001-F02
I2: Versión | J2: 1
I3: Página | J3: 1 de 1
D4: CONTROL DE CALIDAD A GRANEL | I4: Vigencia | J4: Desde: 17-Mar-2025
J5: Hasta: 16-Mar-2028
B6: NOMBRE DEL PRODUCTO: | D6: ='INSTRUCTIVO FAB'!F7 -> SUERO HIDRATANTE AH 1.5% | G6: FECHA DE FABRICACIÓN:
B7: N° OP: | D7: ='INSTRUCTIVO FAB'!F9 -> OP-L-131 | G7: FECHA DE ANALISIS:
B8: N° LOTE: | D8: ='INSTRUCTIVO FAB'!F8 -> 252671 | G8: FORMA COSMETICA: | I8: =OP!G11 -> SOLUCION
B9: TAMAÑO DE LOTE: | D9: =OP!P12 -> 90 | G9: FECHA DE VENCIMIENTO:
B10: PRUEBAS DE CONTROL DE CALIDAD
B11: Propiedades fisicoquímicas | D11: Especificación | I11: Resultado
I12: Valor | J12: C | K12: NC
B13: Aspecto | D13: Líquida y ligeramente viscosa, transparente, con un ligero tono opaco, muy leve o casi imperceptible
B14: Viscosidad | D14: INFORMATIVO
B15: Densidad | D15: 0,999 - 1,100 g/cm³
B16: pH | D16: 5.5 - 6.0
B17: C=Cumple; NC= No cumple
B18: OBSERVACIONES
B23: ESTADO DE CALIDAD
C24: APROBADO | F24: RECHAZADO | J24: CUARENTENA
B26: REALIZADO POR | G26: VERIFICADO Y APROBADO POR
B27: CARGO | G27: CARGO
B28: FECHA | G28: FECHA

Sheet ORDEN ENVASADO
D1: FORMATO | M1: Código | O1: PRD-PRO-001-F06
M2: Versión | O2: 1
D3: ORDEN Y CONTROL DE ENVASADO | M3: Página | O3: 1 de 1
M4: Vigencia | O4: Desde: 04-Mar-2025
O5: Hasta: 03-Mar-2028
A6: NOMBRE DEL PRODUCTO | F6: ='COC GRANEL'!D6 -> SUERO HIDRATANTE AH 1.5%
A7: NÚMERO DE LOTE | F7: ='COC GRANEL'!D8 -> 252671 | H7: N° OP | J7: ='COC GRANEL'!D7 -> OP-L-131 | M7: PRESENTACIÓN | O7: 30 mL
A8: UNIDADES TEÓRICAS | H8: FECHA DE INICIO | M8: FECHA FIN
A9: UNIDADES ENTREGADAS | H9: HORA INICIO/HORA FIN | M9: TIEMPO EN HORAS:
A10: DESPEJE Y LIBERACIÓN DEL ÁREA: | N10: SI | P10: NO
A11: Se encuentra diligenciado el campo del área a usar en el formato PRD-PRO-001-F02
A12: PROCESO DE ENVASADO
A13: CÓDIGO INTERNO | C13: LOTE | F13: NOMBRE DEL MATERIAL | M13: CANTIDAD ENTREGADA | O13: AVERÍAS
A14: EN-TR-VI-030-01 | C14: N/A | F14: Frasco Vidrio Transpartente 30ml | M14: =F8 -> 0
A15: TA-GO-BL-072-01 | C15: N/A | F15: Gotero Blanco 72 mm | M15: =F8 -> 0
A16: N/A | C16: N/A | F16: Etiquetas Suero Hidratante Acido Hialuronico 30mL | M16: =F8 -> 0
A17: N/A | C17: N/A | F17: Caja Plegadiza Suero Hidratante Acido Hialuronico 30mL | M17: =F8 -> 0
A19: PRODUCTO PENDIETE | G19: SI | K19: NO | M19: CANTIDAD
A20: REALIZADO POR: | H20: VERIFICADO POR: | N20: FECHA:
A21: CONTROL EN PROCESO
A22: VOLUMEN TEÓRICO (mL) | L22: DENSIDAD (g/mL)
A23: MASA (g) | L23: RANGO LLENADO
A24: PARÁMETROS GAVIMÉTRICOS
A25: Ensayo | C25: HORA | E25: REALIZADO POR | H25: Tara 1 | K25: Tara 2 | L25: Tara 3 | M25: Tara 4 | N25: Tara 5 | P25: Promedio Tara
A27: CONTROL DE LLENADO
A28: FECHA | C28: HORA | E28: REALIZADO POR | H28: Peso 1 | K28: Peso 2 | L28: Peso 3 | M28: Peso 4 | N28: Peso 5 | P28: PROMEDIO
A35: Peso Bruto Final
A36: Peso Neto Final
A37: Coeficiente de Variación
A38: CONCILIACIÓN DE MATERIALES
A39: ENVASES ENTREGADOS | L39: ENVASES RECHAZADOS
A40: TAPAS ENTREGADAS | L40: TAPAS RECHAZADAS
A41: GOTEROS ENTREGADOS | L41: GOTEROS RECHAZADOS
A42: Observaciones:
A44: Realizado o entregado por: | K44: Verificado o recibido por:
A45: Cargo: | K45: Cargo:
A46: Fecha: | K46: Fecha:

Sheet Copia de ORDEN ENVASADO 1
D1: FORMATO | M1: Código | O1: PRD-PRO-001-F06
M2: Versión | O2: 1
D3: ORDEN Y CONTROL DE ENVASADO | M3: Página | O3: 1 de 1
M4: Vigencia | O4: Desde: 04-Mar-2025
O5: Hasta: 03-Mar-2028
A6: NOMBRE DEL PRODUCTO | F6: ='COC GRANEL'!D6 -> SUERO HIDRATANTE AH 1.5%
A7: NÚMERO DE LOTE | F7: ='COC GRANEL'!D8 -> 252671 | H7: N° OP | J7: ='COC GRANEL'!D7 -> OP-L-131 | M7: PRESENTACIÓN | O7: 10 mL
A8: UNIDADES TEÓRICAS | H8: FECHA DE INICIO | M8: FECHA FIN
A9: UNIDADES ENTREGADAS | H9: HORA INICIO/HORA FIN | M9: TIEMPO EN HORAS:
A10: DESPEJE Y LIBERACIÓN DEL ÁREA: | N10: SI | P10: NO
A11: Se encuentra diligenciado el campo del área a usar en el formato PRD-PRO-001-F02
A12: PROCESO DE ENVASADO
A13: CÓDIGO INTERNO | C13: LOTE | F13: NOMBRE DEL MATERIAL | M13: CANTIDAD ENTREGADA | O13: AVERÍAS
A14: EN-AZ-VI-010-01 | C14: N/A | F14: ENVASE VIDRIO AZUL10 mL | M14: =F8 -> 0
A15: TA-NE-GO-055-01 | C15: N/A | F15: GOTERO BLANCO 55 mm | M15: =F8 -> 0
A19: PRODUCTO PENDIETE | G19: SI | K19: NO | M19: CANTIDAD
A20: REALIZADO POR: | H20: VERIFICADO POR: | N20: FECHA:
A21: CONTROL EN PROCESO
A22: VOLUMEN TEÓRICO (mL) | L22: DENSIDAD (g/mL)
A23: MASA (g) | L23: RANGO LLENADO
A24: PARÁMETROS GAVIMÉTRICOS
A25: Ensayo | C25: HORA | E25: REALIZADO POR | H25: Tara 1 | K25: Tara 2 | L25: Tara 3 | M25: Tara 4 | N25: Tara 5 | P25: Promedio Tara
A27: CONTROL DE LLENADO
A28: FECHA | C28: HORA | E28: REALIZADO POR | H28: Peso 1 | K28: Peso 2 | L28: Peso 3 | M28: Peso 4 | N28: Peso 5 | P28: PROMEDIO
A35: Peso Bruto Final
A36: Peso Neto Final
A37: Coeficiente de Variación
A38: CONCILIACIÓN DE MATERIALES
A39: ENVASES ENTREGADOS | L39: ENVASES RECHAZADOS
A40: TAPAS ENTREGADAS | L40: TAPAS RECHAZADAS
A41: GOTEROS ENTREGADOS | L41: GOTEROS RECHAZADOS
A42: Observaciones:
A44: Realizado o entregado por: | K44: Verificado o recibido por:
A45: Cargo: | K45: Cargo:
A46: Fecha: | K46: Fecha:

Sheet ACONDICIONAMIENTO
D1: FORMATO | M1: Código | O1: PRD-PRO-001-F07
M2: Versión | O2: 1
D3: ACONDICIONAMIENTO Y EMPAQUE | M3: Página | O3: 1 de 1
M4: Vigencia | O4: Desde: 04-Mar-2025
O5: Hasta: 03-Mar-2028
A7: NOMBRE DEL PRODUCTO | F7: ='ORDEN ENVASADO'!F6 -> SUERO HIDRATANTE AH 1.5%
A8: NÚMERO DE LOTE | F8: ='ORDEN ENVASADO'!F7 -> 252671 | H8: N° OP | J8: ='ORDEN ENVASADO'!J7 -> OP-L-131 | M8: PRESENTACIÓN | O8: 30 mL
A9: UNIDADES ENTREGADAS | H9: FECHA DE INICIO | M9: FECHA FIN
A10: HORA INICIO | H10: HORA FIN | M10: TIEMPO EN HORAS:
A11: DESPEJE Y LIBERACIÓN DEL ÁREA: | N11: SI | P11: NO
A12: Se encuentra diligenciado el campo del área a usar en el formato PRD-PRO-001-F02
A13: TAREAS A REALIZAR (Marque con una X)
A14: LOTEAR: | D14: F.VENCIMIENTO: | G14: ETIQUETA: | I14: PLEGADIZA: | M14: STICKER: | O14: KIT:
A15: LOTEADO (INFORMACION A CODIFICAR)
A16: VARIABLES | D16: DESCRIPCIÓN | M16: REALIZADO POR | O16: VERIFICADO POR
A17: No. de lote
A18: Fecha de vencimiento
A19: INDICADORES
A20: PARAMETRO | C20: FECHA | F20: HORA INICIO | H20: HORA FIN | J20: TIEMPO TOTAL EN HORAS | M20: CANT PERSONAS | O20: UNIDADES:
A21: LOTEADO | F21: AM-PM | H21: AM-PM
A22: ETIQUETADO | F22: AM-PM | H22: AM-PM
A23: CAJA PLEGADIZA | F23: AM-PM | H23: AM-PM
A24: STICKER | F24: AM-PM | H24: AM-PM
A25: KIT | F25: AM-PM | H25: AM-PM
A26: ENTREGADO POR: | F26: FECHA: | J26: RECIBIDO POR: | O26: FECHA:
A27: EMBALAJE
A28: CANTIDAD DE UNIDADES POR CAJA
A29: CANTIDAD DE CAJAS
A30: FECHA INICIO
A31: FECHA FIN
A32: HORA INICIO
A33: HORA FIN
A34: REALIZADO POR:
A35: VERIFICADO POR: | M35: FECHA
A36: OBSERVACIONES:
A39: REVISADO POR: | M39: FECHA:
A40: CARGO:

Sheet Copia de ACONDICIONAMIENTO
D1: FORMATO | M1: Código | O1: PRD-PRO-001-F07
M2: Versión | O2: 1
D3: ACONDICIONAMIENTO Y EMPAQUE | M3: Página | O3: 1 de 1
M4: Vigencia | O4: Desde: 04-Mar-2025
O5: Hasta: 03-Mar-2028
A7: NOMBRE DEL PRODUCTO | F7: ='ORDEN ENVASADO'!F6 -> SUERO HIDRATANTE AH 1.5%
A8: NÚMERO DE LOTE | F8: ='ORDEN ENVASADO'!F7 -> 252671 | H8: N° OP | J8: ='ORDEN ENVASADO'!J7 -> OP-L-131 | M8: PRESENTACIÓN | O8: 10 mL
A9: UNIDADES ENTREGADAS | H9: FECHA DE INICIO | M9: FECHA FIN
A10: HORA INICIO | H10: HORA FIN | M10: TIEMPO EN HORAS:
A11: DESPEJE Y LIBERACIÓN DEL ÁREA: | N11: SI | P11: NO
A12: Se encuentra diligenciado el campo del área a usar en el formato PRD-PRO-001-F02
A13: TAREAS A REALIZAR (Marque con una X)
A14: LOTEAR: | D14: F.VENCIMIENTO: | G14: ETIQUETA: | I14: PLEGADIZA: | M14: STICKER: | O14: KIT:
A15: LOTEADO (INFORMACION A CODIFICAR)
A16: VARIABLES | D16: DESCRIPCIÓN | M16: REALIZADO POR | O16: VERIFICADO POR
A17: No. de lote
A18: Fecha de vencimiento
A19: INDICADORES
A20: PARAMETRO | C20: FECHA | F20: HORA INICIO | H20: HORA FIN | J20: TIEMPO TOTAL EN HORAS | M20: CANT PERSONAS | O20: UNIDADES:
A21: LOTEADO | F21: AM-PM | H21: AM-PM
A22: ETIQUETADO | F22: AM-PM | H22: AM-PM
A23: CAJA PLEGADIZA | F23: AM-PM | H23: AM-PM
A24: STICKER | F24: AM-PM | H24: AM-PM
A25: KIT | F25: AM-PM | H25: AM-PM
A26: ENTREGADO POR: | F26: FECHA: | J26: RECIBIDO POR: | O26: FECHA:
A27: EMBALAJE
A28: CANTIDAD DE UNIDADES POR CAJA
A29: CANTIDAD DE CAJAS
A30: FECHA INICIO
A31: FECHA FIN
A32: HORA INICIO
A33: HORA FIN
A34: REALIZADO POR:
A35: VERIFICADO POR: | M35: FECHA
A36: OBSERVACIONES:
A39: REVISADO POR: | M39: FECHA:
A40: CARGO:

Sheet ESTADO DE LIMPIEZA DE A Y E
C1: FORMATO | H1: Código | I1: PRD-PRO-002-F02
H2: Versión | I2: 1
H3: Página | I3: 1 de 1
C4: ESTADO DE LIMPIEZA DE ÁREAS Y EQUIPOS | H4: Vigencia | I4: Desde: 05-Mar-2025
I5: Hasta: 04-Mar-2028
B8: FORMATO | G8: Código | H8: PRD-PRO-002-F02
G9: Versión | H9: 1
G10: Página | H10: 1 de 1
B11: ESTADO DE LIMPIEZA DE ÁREAS Y EQUIPOS | G11: Vigencia | H11: Desde: 05-Mar-2025
H12: Hasta: 04-Mar-2028
A13: Nombre Área/Equipo:
A14: Código (Si aplica): | G14: Fecha:
A15: Producto anterior: | G15: Lote:
A16: Producto en proceso: | G16: Lote:
A17: Sanitizante Utilizado:
A18: Realizado por: | G18: FECHA:
A19: Verificado por: | G19: FECHA:
B21: FORMATO | G21: Código | H21: PRD-PRO-002-F02
G22: Versión | H22: 1
G23: Página | H23: 1 de 1
B24: ESTADO DE LIMPIEZA DE ÁREAS Y EQUIPOS | G24: Vigencia | H24: Desde: 05-Mar-2025
H25: Hasta: 04-Mar-2028
A26: Nombre Área/Equipo:
A27: Código (Si aplica): | G27: Fecha:
A28: Producto anterior: | G28: Lote:
A29: Producto en proceso: | G29: Lote:
A30: Sanitizante Utilizado:
A31: Realizado por: | G31: FECHA:
A32: Verificado por: | G32: FECHA:
B34: FORMATO | G34: Código | H34: PRD-PRO-002-F02
G35: Versión | H35: 1
G36: Página | H36: 1 de 1
B37: ESTADO DE LIMPIEZA DE ÁREAS Y EQUIPOS | G37: Vigencia | H37: Desde: 05-Mar-2025
H38: Hasta: 04-Mar-2028
A39: Nombre Área/Equipo:
A40: Código (Si aplica): | G40: Fecha:
A41: Producto anterior: | G41: Lote:
A42: Producto en proceso: | G42: Lote:
A43: Sanitizante Utilizado:
A44: Realizado por: | G44: FECHA:
...

Sheet COA PT
D1: FORMATO | K1: Código | L1: COC-PRO-001-F03
K2: Versión | L2: 1
K3: Página | L3: 1 de 1
D4: CERTIFICADO DE ÁNALISIS DE PRODUCTO TERMINADO | K4: Vigencia | L4: Desde: 17-Mar-2025
L5: Hasta: 16-Mar-2028
B6: NOMBRE DEL PRODUCTO: | D6: ='ORDEN ENVASADO'!F6 -> SUERO HIDRATANTE AH 1.5% | J6: FECHA DE ÁNALISIS:
B7: N° LOTE | D7: =ACONDICIONAMIENTO!F8 -> 252671 | F7: N° O.P | H7: =ACONDICIONAMIENTO!J8 -> OP-L-131 | J7: FECHA DE VENCIMIENTO:
B8: FORMA COSMETICA | D8: =OP!G11 -> SOLUCION | J8: TOTAL DE UNIDADES:
B9: Unidades a inspeccionar según muestreo
B11: Parámetro | D11: Especificación | G11: Metodología | I11: Resultado | K11: Concepto de Calidad | L11: Fecha de análisis
B12: Análisis organoléptico | C12: Color | D12: Transparente o ligeramente opaco | G12: Organoléptico
C13: Olor | D13: Inodoro | G13: Organoléptico
C14: Apariencia | D14: ='COC GRANEL'!D13 -> Líquida y ligeramente viscosa, transparente, con un ligero tono opaco, muy leve o casi imperceptible | G14: Organoléptico
B15: Análisis Fisicoquímico | C15: pH | D15: ='COC GRANEL'!D16 -> 5.5 - 6.0 | G15: Interna
C16: Densidad | D16: ='COC GRANEL'!D15 -> 0,999 - 1,100 g/cm³ | G16: Interna
C17: Viscosidad | D17: Informativo | G17: Interna
B18: Análisis Microbiológico | C18: Mesófilos aerobio totales | D18: < 5 x 10^2 UFC/g o ml | G18: USP-NF 2023 <62>
C19: Pseudomonas aeruginosa | D19: Ausencia en 1g o ml | G19: USP-NF 2023 <62>
C20: Staphylococcus aureus | D20: Ausencia en 1g o ml | G20: USP-NF 2023 <62>
C21: Escherichia coli | D21: Ausencia en 1g o ml | G21: USP-NF 2023 <62>
B22: Cantidad muestra de retención (g): | G22: Unidades de retención:
B23: Observaciones:
B26: Concepto: CUMPLE ( ) NO CUMPLE ( )
B27: Realizado por: | H27: Aprobado por:
B28: Cargo: | H28: Cargo:
B29: Fecha: | H29: Fecha:

Sheet ROTULO DE DISPENSACION
C1: FORMATO | G1: Código | H1: PRD-PRO-001-F08
G2: Versión | H2: 1
G3: Página | H3: 1 de 1
C4: RÓTULO MATERIA PRIMA DISPENSADA | G4: Vigencia | H4: Desde: 04-Mar-2025
H5: Hasta: 03-Mar-2028
B6: OP: | C6: =OP!$M$11 -> OP-L-131 | G6: Fecha:
B7: Producto a fabricar: | C7: =OP!$G$9 -> SUERO HIDRATANTE AH 1.5% | G7: Lote del Producto: | H7: =OP!$M$10 -> 252671
B8: Nombre MP: | C8: =OP!B15 -> AGUA DESIONIZADA | G8: Lote MP: | H8: =OP!J15 -> AD-251981
B9: Peso teórico: | C9: =OP!N15 -> 85689
B10: Tara:
B11: Peso Neto: | G11: Pesado por:
B12: Peso Bruto: | G12: Verificado por:
B13: MP: Materia Prima
C16: FORMATO | G16: Código | H16: PRD-PRO-001-F08
G17: Versión | H17: 1
G18: Página | H18: 1 de 1
C19: RÓTULO MATERIA PRIMA DISPENSADA | G19: Vigencia | H19: Desde: 04-Mar-2025
H20: Hasta: 03-Mar-2028
B21: OP: | C21: =OP!$M$11 -> OP-L-131 | G21: Fecha:
B22: Producto a fabricar: | C22: =OP!$G$9 -> SUERO HIDRATANTE AH 1.5% | G22: Lote del Producto: | H22: =OP!$M$10 -> 252671
B23: Nombre MP: | C23: =OP!B16 -> GLICERINA | G23: Lote MP: | H23: =OP!J16 -> 021067-25
B24: Peso teórico: | C24: =OP!N16 -> 900
B25: Tara:
B26: Peso Neto: | G26: Pesado por:
B27: Peso Bruto: | G27: Verificado por:
B28: MP: Materia Prima
C31: FORMATO | G31: Código | H31: PRD-PRO-001-F08
G32: Versión | H32: 1
G33: Página | H33: 1 de 1
C34: RÓTULO MATERIA PRIMA DISPENSADA | G34: Vigencia | H34: Desde: 04-Mar-2025
H35: Hasta: 03-Mar-2028
B36: OP: | C36: =OP!$M$11 -> OP-L-131 | G36: Fecha:
B37: Producto a fabricar: | C37: =OP!$G$9 -> SUERO HIDRATANTE AH 1.5% | G37: Lote del Producto: | H37: =OP!$M$10 -> 252671
B38: Nombre MP: | C38: =OP!B17 -> FENOXIETANOL | G38: Lote MP: | H38: =OP!J17 -> 871931
B39: Peso teórico: | C39: =OP!N17 -> 900
B40: Tara:
B41: Peso Neto: | G41: Pesado por:
B42: Peso Bruto: | G42: Verificado por:
B43: MP: Materia Prima
C45: FORMATO | G45: Código | H45: PRD-PRO-001-F08
...

Sheet INSPECCIÓN ETIQUETAS 1
D1: FORMATO | J1: Código | K1: COC-PRO-001-F04
J2: Versión | K2: 1
J3: Página | K3: 1 de 1
D4: INSPECCIÓN DE ETIQUETAS | J4: Vigencia | K4: Desde: 17-Mar-2025
K5: Hasta: 16-Mar-2028
B8: NOMBRE DEL PRODUCTO | C8: ='COA PT'!D6 -> SUERO HIDRATANTE AH 1.5% | G8: NOTIFICACIÓN SANITARIA | H8: =OP!G10 -> NSOC36908-25CO
B9: N° OP | C9: ='COA PT'!H7 -> OP-L-131 | G9: FECHA DE VENCIMIENTO | H9: =OP!P10 -> 0
B10: N° LOTE | C10: ='COA PT'!D7 -> 252671 | G10: PRESENTACIÓN | H10: ='ORDEN ENVASADO'!O7 -> 30 mL
B12: VERIFICACIÓN DE INFORMACIÓN DE LA ETIQUETA
B13: ITEM | C13: DOCUMENTO | H13: CONCEPTO | J13: OBSERVACIONES
B14: 1 | C14: La etiqueta se encuentra en letra legible e idioma español
B15: 2 | C15: La etiqueta cuenta con la siguiente información: Nombre del producto y su denominación genérica
B16: 3 | C16: Nombre o razón social del titular de la NSO o del importador paralelo, número de NSO.
B17: 4 | C17: Contenido nominal (ml, g), número de lote, fecha de vencimiento o vida útil
B18: 5 | C18: Ingredientes INCI que impliquen riesgo sanitario (Para productos de 10ml o menos)
B19: 6 | C19: Ingredientes completos INCI (Para productos de 10ml o menos, solo aplica el numeral 5)
B20: 7 | C20: Grupo cosmetico y marca comercial (cuando corresponda)
B21: 8 | C21: Pais de origen
B22: 9 | C22: Precauciones particulares de uso sobre sustancias o ingredientes
B23: 10 | C23: Instrucciones de uso (cuando sea necesario)
B24: 11 | C24: Condiciones de almacenamiento (si aplica)
B25: 12 | C25: Advertencias, precauciones y restricciones para uso del producto
B27: OBSERVACIONES:
B30: ETIQUETA TESTIGO
B32: ESTADO
B33: APROBADO POR: | J33: FECHA
B34: CARGO:
B35: CUMPLE: C NO CUMPLE: NC NO APLICA: NA

Sheet PRODUCTO EN PROCESO
C1: FORMATO | I1: Código | J1: PRD-PRO-001-F10
I2: Versión | J2: 1
I3: Página | J3: 1 de 1
C4: PRODUCTO EN PROCESO | I4: Vigencia | J4: Desde: 04-Mar-2025
J5: Hasta: 03-Mar-2028
C8: FORMATO | D8: Código | E8: PRD-PRO-001-F10 | H8: FORMATO | I8: Código | J8: PRD-PRO-001-F10
D9: Versión | E9: 1 | I9: Versión | J9: 1
D10: Página | E10: 1 de 1 | I10: Página | J10: 1 de 1
C11: PRODUCTO EN PROCESO | D11: Vigencia | E11: Desde: 04-Mar-2025 | H11: PRODUCTO EN PROCESO | I11: Vigencia | J11: Desde: 04-Mar-2025
E12: Hasta: 03-Mar-2028 | J12: Hasta: 03-Mar-2028
B13: Nombre del producto: | C13: ='INSPECCIÓN ETIQUETAS 1'!C8 -> SUERO HIDRATANTE AH 1.5% | G13: Nombre del producto: | H13: =C13 -> SUERO HIDRATANTE AH 1.5%
B14: Lote: | C14: ='INSPECCIÓN ETIQUETAS 1'!C10 -> 252671 | D14: Fecha: | G14: Lote: | H14: =C14 -> 252671 | I14: Fecha:
B15: Numero de Op: | C15: ='INSPECCIÓN ETIQUETAS 1'!C9 -> OP-L-131 | G15: Numero de Op: | H15: =C15 -> OP-L-131
B16: Tamaño del lote: | C16: =OP!P12 -> 90 | G16: Tamaño del lote: | H16: =C16 -> 90
B17: OBSERVACIONES | G17: OBSERVACIONES
B21: REALIZADO POR | G21: REALIZADO POR
C23: FORMATO | D23: Código | E23: PRD-PRO-001-F10 | H23: FORMATO | I23: Código | J23: PRD-PRO-001-F10
D24: Versión | E24: 1 | I24: Versión | J24: 1
D25: Página | E25: 1 de 1 | I25: Página | J25: 1 de 1
C26: PRODUCTO EN PROCESO | D26: Vigencia | E26: Desde: 04-Mar-2025 | H26: PRODUCTO EN PROCESO | I26: Vigencia | J26: Desde: 04-Mar-2025
E27: Hasta: 03-Mar-2028 | J27: Hasta: 03-Mar-2028
B28: Nombre del producto: | G28: Nombre del producto:
B29: Lote: | D29: Fecha: | G29: Lote: | I29: Fecha:
B30: Numero de Op: | G30: Numero de Op:
B31: Tamaño del lote: | G31: Tamaño del lote:
B32: OBSERVACIONES | G32: OBSERVACIONES
B36: REALIZADO POR | G36: REALIZADO POR
C38: FORMATO | D38: Código | E38: PRD-PRO-001-F10 | H38: FORMATO | I38: Código | J38: PRD-PRO-001-F10
D39: Versión | E39: 1 | I39: Versión | J39: 1
D40: Página | E40: 1 de 1 | I40: Página | J40: 1 de 1
C41: PRODUCTO EN PROCESO | D41: Vigencia | E41: Desde: 04-Mar-2025 | H41: PRODUCTO EN PROCESO | I41: Vigencia | J41: Desde: 04-Mar-2025
E42: Hasta: 03-Mar-2028 | J42: Hasta: 03-Mar-2028
B43: Nombre del producto: | G43: Nombre del producto:
B44: Lote: | D44: Fecha: | G44: Lote:
B45: Numero de Op: | G45: Numero de Op:
B46: Tamaño del lote: | G46: Tamaño del lote:
B47: OBSERVACIONES | G47: OBSERVACIONES
B51: REALIZADO POR | G51: REALIZADO POR
C53: FORMATO | D53: Código | E53: PRD-PRO-001-F10 | H53: FORMATO | I53: Código | J53: PRD-PRO-001-F10
D54: Versión | E54: 1 | I54: Versión | J54: 1
...

Sheet INSPECCIÓN DE PRODUCTO FINAL
D1: FORMATO | J1: Código | K1: COC-PRO-001-F05
J2: Versión | K2: 1
J3: Página | K3: 1 de 1
D4: INSPECCIÓN DE PRODUCTO TERMINADO | J4: Vigencia | K4: Desde: 17-Mar-2025
K5: Hasta: 16-Mar-2028
B8: PRODUCTO | C8: ='LISTA CHEQUEO'!F7 -> SUERO HIDRATANTE AH 1.5% | G8: MARCA O CLIENTE: | H8: ='LISTA CHEQUEO'!F10 -> ANIMUS LAB
B9: NOTIFICACIÓN SANITARIA | C9: ='LISTA CHEQUEO'!F11 -> NSOC36908-25CO | E9: N° O.P | F9: ='LISTA CHEQUEO'!M8 -> OP-L-131 | H9: N° LOTE | J9: ='LISTA CHEQUEO'!F8 -> 252671
B10: UNIDADES TOTALES | E10: UNIDAD DE EMPAQUE | H10: N° UNIDADES ANALIZADAS
B11: FECHAS DE ANALISIS | E11: N° DE CAJAS TOTALES | H11: N° DE CAJAS INSPECCIONADAS
B12: PRESENTACIÓN
B14: VERIFICACIÓN DE DOCUMENTOS
B15: PÁRAMETRO | C15: ESPECIFICACIÓN | H15: CONCEPTO | J15: OBSERVACIONES
B16: ETIQUETADO | C16: ETIQUETA ACORDE A LO ESTIPULADO EN COC-PRO-001-F04 LISTA DE CHEQUEO DE ETIQUETAS
B17: ADHERENCIA | C17: LA ETIQUETA ESTA COMPLETAMENTE ADHERIDA AL ENVASE, SIN DESPRENDIMIENTOS, BORDES LEVANTADOS O BURBUJAS
B18: LEGIBILIDAD | C18: LA INFORMACIÓN ES CLARA, LEGIBLE, SIN MANCHAS NI ERRORES DE IMPRESIÓN
B19: INTEGRIDAD | C19: LA ETIQUETA NO PRESENTA ARRUGAS, RASGADURAS NI DECOLORACIONES
B20: ALINEACIÓN | C20: LA ETIQUETA ESTA CENTRADA CORRECTAMENTE SEGÚN LAS ESPECIFICACIONES DEL ENVASE
B21: ASPECTO DEL PRODUCTO | C21: EL PRODUCTO EN GENERAL PRESENTA BUEN ASPECTO
B22: SELLADO | C22: CONTINUO, CONFORME Y SIN INTERRUPCIONES VISIBLES
B23: DERRAMES | C23: EL PRODUCTO NO PRESENTA RESIDUOS DE DERRAMES VISIBLES DENTRO O FUERA DEL ENVASE
B24: PARTICULAS | C24: EL PRODUCTO SE ENCUENTRA LIBRE DE PARTICULAS EXTRAÑAS
B25: ASPECTO FINAL | C25: ENVASE/EMPAQUE LIMPIO, EN PERFECTAS CONDICIONES (SIN ABOLLADORAS, RASPONES, GRIETAS O MANCHAS)
B26: ASPECTO CAJA PLEGADIZA | C26: BUEN ASPECTO, (LIMPIA, SIN MANCHAS NI ARRUGAS)
B27: IMPRESIÓN | C27: LA IMPRESIÓN ES NÍTIDA, SIN MANCHAS, BORRONES O DECOLORACIONES
... B29: LIMPIEZA | C29: LA CAJA ESTA LIBRE DE SUCIEDAD TIPO POLVO, RESTOS DE PEGAMENTO O PARTICULAS EXTRAÑAS
B31: OBSERVACIONES:
B35: ESTADO DE CALIDAD | E35: APROBADO | H35: RECHAZADO | K35: CUARENTENA
B36: REALIZADO POR: | H36: FECHA
B37: APROBADO POR: | H37: FECHA DE APROBACIÓN
B38: CARGO QUE APROBÓ:
B40: CUMPLE: C NO CUMPLE: NC NO APLICA: NA

Sheet ENVASADO NO CONTINUO
C1: FORMATO | I1: Código | J1: PRD-PRO-001-F09
I2: Versión | J2: 1
I3: Página | J3: 1 de 1
C4: ENVASADO NO CONTINUO | I4: Vigencia | J4: Desde: 04-Mar-2025
J5: Hasta: 03-Mar-2028
C8: FORMATO | D8: Código | E8: PRD-PRO-001-F09 | H8: FORMATO | I8: Código | J8: PRD-PRO-001-F09
D9: Versión | E9: 1 | I9: Versión | J9: 1
D10: Página | E10: 1 de 1 | I10: Página | J10: 1 de 1
C11: ENVASADO NO CONTINUO | D11: Vigencia | E11: Desde: 04-Mar-2025 | H11: ENVASADO NO CONTINUO | I11: Vigencia | J11: Desde: 04-Mar-2025
E12: Hasta: 03-Mar-2028 | J12: Hasta: 03-Mar-2028
B13: Nombre del producto: | G13: Nombre del producto:
B14: Lote: | G14: Lote:
B15: Motivo de no envasado | G15: Motivo de no envasado
B16: Fecha de Elaboración: | D16: Fecha de Envasado: | G16: Fecha de Elaboración: | I16: Fecha de Envasado:
B17: OBSERVACIONES | G17: OBSERVACIONES
B21: REALIZADO POR | G21: REALIZADO POR
B22: VERIFICADO POR | D22: FECHA | G22: VERIFICADO POR | I22: FECHA
C24: FORMATO | D24: Código | E24: PRD-PRO-001-F09 | H24: FORMATO | I24: Código | J24: PRD-PRO-001-F09
D25: Versión | E25: 1 | I25: Versión | J25: 1
D26: Página | E26: 1 de 1 | I26: Página | J26: 1 de 1
C27: ENVASADO NO CONTINUO | D27: Vigencia | E27: Desde: 04-Mar-2025 | H27: ENVASADO NO CONTINUO | I27: Vigencia | J27: Desde: 04-Mar-2025
E28: Hasta: 03-Mar-2028 | J28: Hasta: 03-Mar-2028
B29: Nombre del producto: | G29: Nombre del producto:
B30: Lote: | G30: Lote:
B31: Motivo de no envasado | G31: Motivo de no envasado
B32: Fecha de Elaboración: | D32: Fecha de Envasado: | G32: Fecha de Elaboración: | I32: Fecha de Envasado:
B33: OBSERVACIONES | G33: OBSERVACIONES
B37: REALIZADO POR | G37: REALIZADO POR
B38: VERIFICADO POR | D38: FECHA | G38: VERIFICADO POR | I38: FECHA
C40: FORMATO | D40: Código | E40: PRD-PRO-001-F09 | H40: FORMATO | I40: Código | J40: PRD-PRO-001-F09
D41: Versión | E41: 1 | I41: Versión | J41: 1
D42: Página | E42: 1 de 1 | I42: Página | J42: 1 de 1
C43: ENVASADO NO CONTINUO | D43: Vigencia | E43: Desde: 04-Mar-2025 | H43: ENVASADO NO CONTINUO | I43: Vigencia | J43: Desde: 04-Mar-2025
E44: Hasta: 03-Mar-2028 | J44: Hasta: 03-Mar-2028
B45: Nombre del producto: | G45: Nombre del producto:
B46: Lote: | G46: Lote:
B47: Motivo de no envasado | G47: Motivo de no envasado
B48: Fecha de Elaboración: | D48: Fecha de Envasado: | G48: Fecha de Elaboración: | I48: Fecha de Envasado:
B49: OBSERVACIONES | G49: OBSERVACIONES
B53: REALIZADO POR | G53: REALIZADO POR
...

Sheet ROTULO PT
C1: FORMATO | I1: Código | J1: COC-PRO-001-F06
I2: Versión | J2: 1
I3: Página | J3: 1 de 1
C4: ROTULO DE IDENTIFICACIÓN DE PRODUCTO TERMINADO | I4: Vigencia | J4: Desde: 17-Mar-2025
J5: Hasta: 16-Mar-2028
C8: FORMATO | D8: Código | E8: COC-PRO-001-F06 | H8: FORMATO | I8: Código | J8: COC-PRO-001-F06
D9: Versión | E9: 1 | I9: Versión | J9: 1
C10: ROTULO DE IDENTIFICACIÓN DE PRODUCTO TERMINADO | D10: Página | E10: 1 de 1 | H10: ROTULO DE IDENTIFICACIÓN DE PRODUCTO TERMINADO | I10: Página | J10: 1 de 1
D11: Vigencia | E11: Desde: 17-Mar-2025 | I11: Vigencia | J11: Desde: 17-Mar-2025
E12: Hasta: 16-Mar-2028 | J12: Hasta: 16-Mar-2028
B13: Nombre del producto: | G13: Nombre del producto:
B14: Lote: | D14: Fecha de Fabricación | G14: Lote: | I14: Fecha de Fabricación
B15: Numero de Op: | D15: Cantidad | G15: Numero de Op: | I15: Cantidad
B16: Condiciones de Almacenamiento: | D16: Contenedor número: | G16: Contenedor numero: | I16: Contenedor número:
B17: Observaciones | G17: Observaciones
B21: ESTADO | D21: Aprobado Por: | G21: ESTADO | I21: Aprobado Por:
D23: Fecha: | I23: Fecha:
C26: FORMATO | D26: Código | E26: COC-PRO-001-F06 | H26: FORMATO | I26: Código | J26: COC-PRO-001-F06
D27: Versión | E27: 1 | I27: Versión | J27: 1
C28: ROTULO DE IDENTIFICACIÓN DE PRODUCTO TERMINADO | D28: Página | E28: 1 de 1 | H28: ROTULO DE IDENTIFICACIÓN DE PRODUCTO TERMINADO | I28: Página | J28: 1 de 1
D29: Vigencia | E29: Desde: 17-Mar-2025 | I29: Vigencia | J29: Desde: 17-Mar-2025
E30: Hasta: 16-Mar-2028 | J30: Hasta: 16-Mar-2028
B31: Nombre del producto: | G31: Nombre del producto:
B32: Lote: | D32: Fecha de Fabricación | G32: Lote: | I32: Fecha de Fabricación
B33: Numero de Op: | D33: Cantidad | G33: Numero de Op: | I33: Cantidad
B34: Contenedor numero: | D34: Contenedor número: | G34: Contenedor numero: | I34: Contenedor número:
B35: Observaciones | G35: Observaciones
B39: ESTADO | D39: Aprobado Por: | G39: ESTADO | I39: Aprobado Por:
D41: Fecha: | I41: Fecha:
C44: FORMATO | D44: Código | E44: COC-PRO-001-F06 | H44: FORMATO | I44: Código | J44: COC-PRO-001-F06
D45: Versión | E45: 1 | I45: Versión | J45: 1
C46: ROTULO DE IDENTIFICACIÓN DE PRODUCTO TERMINADO | D46: Página | E46: 1 de 1 | H46: ROTULO DE IDENTIFICACIÓN DE PRODUCTO TERMINADO | I46: Página | J46: 1 de 1
D47: Vigencia | E47: Desde: 17-Mar-2025 | I47: Vigencia | J47: Desde: 17-Mar-2025
E48: Hasta: 16-Mar-2028 | J48: Hasta: 16-Mar-2028
B49: Nombre del producto: | G49: Nombre del producto:
B50: Lote: | D50: Fecha de Fabricación | G50: Lote: | I50: Fecha de Fabricación
B51: Numero de Op: | D51: Cantidad | G51: Numero de Op: | I51: Cantidad
B52: Contenedor numero: | D52: Contenedor número: | G52: Contenedor numero: | I52: Contenedor número:
B53: Observaciones | G53: Observaciones
B57: ESTADO | D57: Aprobado Por: | G57: ESTADO | I57: Aprobado Por:
...
